Workbook

Sheet Users
A1: Users Table
A3: ID | B3: Name | C3: Email | D3: Role | E3: Department | F3: Created At | G3: Column1
A4: 1 | B4: John Doe | C4: john.doe@company.com | D4: Admin | E4: IT | F4: 2025-01-15
A5: 2 | B5: Jane Smith | C5: jane.smith@company.com | D5: Manager | E5: Quality Assurance | F5: 2025-01-16
A6: 3 | B6: Mike Johnson | C6: mike.johnson@company.com | D6: Developer | E6: Frontend Development | F6: 2025-01-17
A7: 4 | B7: Sarah Wilson | C7: sarah.wilson@company.com | D7: Developer | E7: Backend Development | F7: 2025-01-18
A8: 5 | B8: Tom Brown | C8: tom.brown@company.com | D8: QA Engineer | E8: Quality Assurance | F8: 2025-01-19
A9: 6 | B9: Emily Davis | C9: emily.davis@company.com | D9: Product Manager | E9: Product Management | F9: 2025-01-20
A10: 7 | B10: Chris Lee | C10: chris.lee@company.com | D10: DevOps | E10: IT | F10: 2025-01-21

Sheet Departments
A1: Departments Table
A3: ID | B3: Name | C3: Description | D3: Created At
A4: 1 | B4: Frontend Development | C4: Handles UI/UX development and frontend features | D4: 2025-01-01
A5: 2 | B5: Backend Development | C5: Manages server-side logic and database operations | D5: 2025-01-01
A6: 3 | B6: Quality Assurance | C6: Responsible for testing and quality control | D6: 2025-01-01
A7: 4 | B7: Product Management | C7: Oversees product strategy and requirements | D7: 2025-01-01
A8: 5 | B8: IT Support | C8: Provides technical support and infrastructure | D8: 2025-01-01

Sheet Projects
A1: Projects Table
A3: ID | B3: Name | C3: Description | D3: Department | E3: Status | F3: Created At
A4: 1 | B4: E-commerce Platform | C4: Online shopping platform with payment integration | D4: Frontend Development | E4: Active | F4: 2025-01-10
A5: 2 | B5: Mobile App | C5: iOS and Android mobile application | D5: Backend Development | E5: Active | F5: 2025-01-11
A6: 3 | B6: Admin Dashboard | C6: Administrative interface for system management | D6: Quality Assurance | E6: Testing | F6: 2025-01-12
A7: 4 | B7: API Gateway | C7: RESTful API service for external integrations | D7: Backend Development | E7: Active | F7: 2025-01-13
A8: 5 | B8: Customer Portal | C8: Self-service portal for customers | D8: Frontend Development | E8: Development | F8: 2025-01-14

Sheet Issues
A1: Issues Table
A3: ID | B3: Name | C3: Description | D3: Priority | E3: Created At
A4: 1 | B4: Email notification not working | C4: Users are not receiving email notifications for ticket updates | D4: High | E4: 2025-01-15
A5: 2 | B5: Login authentication failure | C5: Users unable to login with valid credentials | D5: High | E5: 2025-01-16
A6: 3 | B6: API rate limiting issues | C6: API endpoints are hitting rate limits too quickly | D6: Medium | E6: 2025-01-17
A7: 4 | B7: Database connection timeout | C7: Database connections are timing out during peak hours | D7: High | E7: 2025-01-18
A8: 5 | B8: Memory leak in background service | C8: Background service is consuming excessive memory | D8: Medium | E8: 2025-01-19
A9: 6 | B9: UI responsiveness issues | C9: User interface is slow to respond to user actions | D9: Medium | E9: 2025-01-20

Sheet Tickets
A1: Tickets Table
A3: ID | B3: Project | C3: Department | D3: Issue | E3: Issue Description | F3: Raised By | G3: Assigned To | H3: Status | I3: Priority | J3: Created At | K3: Updated At | L3: Resolved At | M3: Column1
A4: 1 | B4: E-commerce Platform | C4: Frontend Development | D4: Email notification not working | E4: Users not receiving order confirmation emails | F4: John Doe | G4: Mike Johnson | H4: In Progress | I4: High | J4: 2025-03-15 09:00:00 | K4: 2025-03-15 14:30:00
A5: 2 | B5: Mobile App | C5: Backend Development | D5: Login authentication failure | E5: App crashes during login | F5: Jane Smith | G5: Chris Lee | H5: Resolved | I5: High | J5: 2025-03-16 10:15:00 | K5: 2025-03-18 16:45:00 | L5: 2025-03-18 16:45:00
A6: 3 | B6: Admin Dashboard | C6: Quality Assurance | D6: API rate limiting issues | E6: Dashboard API calls being throttled | F6: Mike Johnson | G6: Tom Brown | H6: In Progress | I6: Medium | J6: 2025-03-17 11:30:00 | K6: 2025-03-17 15:20:00
A7: 4 | B7: API Gateway | C7: Backend Development | D7: Database connection timeout | E7: API gateway unable to connect to database | F7: Sarah Wilson | G7: Chris Lee | H7: Resolved | I7: High | J7: 2025-03-18 08:45:00 | K7: 2025-03-19 12:30:00 | L7: 2025-03-19 12:30:00
A8: 5 | B8: Customer Portal | C8: Frontend Development | D8: Memory leak in background service | E8: Portal becoming slow after extended use | F8: Tom Brown | G8: Mike Johnson | H8: In Progress | I8: Medium | J8: 2025-03-19 13:00:00 | K8: 2025-03-19 17:15:00
A9: 6 | B9: E-commerce Platform | C9: Quality Assurance | D9: UI responsiveness issues | E9: Product page loading slowly | F9: Emily Davis | G9: Tom Brown | H9: Open | I9: Medium | J9: 2025-03-20 09:30:00 | K9: 2025-03-20 09:30:00
A10: 7 | B10: Mobile App | C10: Frontend Development | D10: Email notification not working | E10: Push notifications not working | F10: Chris Lee | G10: Mike Johnson | H10: Resolved | I10: High | J10: 2025-03-21 14:00:00 | K10: 2025-03-22 10:30:00 | L10: 2025-03-22 10:30:00
A11: 8 | B11: API Gateway | C11: Product Management | D11: Login authentication failure | E11: Admin login issues in gateway | F11: John Doe | G11: Sarah Wilson | H11: In Progress | I11: High | J11: 2025-03-22 15:45:00 | K11: 2025-03-22 16:20:00

Sheet Ticket History
A1: Ticket History Table
A3: ID | B3: Ticket ID | C3: Status | D3: Comments | E3: Updated By | F3: Created At
A4: 1 | B4: 1 | C4: Open | D4: Initial ticket created | E4: John Doe | F4: 2025-03-15 09:00:00
A5: 2 | B5: 1 | C5: In Progress | D5: Assigned to Mike Johnson | E5: Jane Smith | F5: 2025-03-15 10:30:00
A6: 3 | B6: 1 | C6: In Progress | D6: Investigating email server configuration | E6: Mike Johnson | F6: 2025-03-15 14:30:00
A7: 4 | B7: 2 | C7: Open | D7: Login issue reported | E7: Jane Smith | F7: 2025-03-16 10:15:00
A8: 5 | B8: 2 | C8: In Progress | D8: Assigned to Chris Lee | E8: Sarah Wilson | F8: 2025-03-16 11:00:00
A9: 6 | B9: 2 | C9: Resolved | D9: Fixed authentication token issue | E9: Chris Lee | F9: 2025-03-18 16:45:00
A10: 7 | B10: 3 | C10: Open | D10: API throttling issue | E10: Mike Johnson | F10: 2025-03-17 11:30:00
A11: 8 | B11: 3 | C11: In Progress | D11: Analyzing API usage patterns | E11: Tom Brown | F11: 2025-03-17 15:20:00
A12: 9 | B12: 4 | C12: Open | D12: Database connection failure | E12: Sarah Wilson | F12: 2025-03-18 08:45:00
A13: 10 | B13: 4 | C13: In Progress | D13: Checking connection pool settings | E13: Chris Lee | F13: 2025-03-18 10:00:00
A14: 11 | B14: 4 | C14: Resolved | D14: Increased connection timeout | E14: Chris Lee | F14: 2025-03-19 12:30:00
A15: 12 | B15: 5 | C15: Open | D15: Memory usage increasing over time | E15: Tom Brown | F15: 2025-03-19 13:00:00
... A21: 18 | B21: 8 | C21: In Progress | D21: Checking admin credentials | E21: Sarah Wilson | F21: 2025-03-22 16:20:00

Sheet DATAFORDASHBOARD
A1: TICKET MANAGEMENT SYSTEM DASHBOARD
A3: Key Performance Indicators
A4: Total Tickets | B4: =COUNT(Tickets!A4:A11) -> 8
A5: Escalation Rate | B5: =0% -> 0
A6: Avg Resolution Time (Hours) | B6: =IFERROR(AVERAGE(IF(Tickets!L4:L11<>"",(Tickets!L4:L11-Tickets!J4:J11)*24,0)),0) -> 0
A7: Total Departments | B7: =COUNTA(Departments!B4:B8) -> 5
A9: Department-wise Ticket Analysis
A10: Department | B10: Ticket Count | C10: Percentage
A11: Frontend Development | B11: =COUNTIF(Tickets!C4:C11,"Frontend Development") -> 3 | C11: =B11/$B$4 -> 0.375
A12: Quality Assurance | B12: =COUNTIF(Tickets!C4:C11,"Quality Assurance") -> 2 | C12: =B12/$B$4 -> 0.25
A13: Backend Development | B13: =COUNTIF(Tickets!C4:C11,"Backend Development") -> 2 | C13: =B13/$B$4 -> 0.25
A14: Product Management | B14: =COUNTIF(Tickets!C4:C11,"Product Management") -> 1 | C14: =B14/$B$4 -> 0.125
A16: Resolution Time Analysis
A17: Ticket ID | B17: Created Date | C17: Resolved Date | D17: Resolution Hours | E17: Column1
A18: 2 | B18: =Tickets!J5 -> 2025-03-16 10:15:00 | C18: =Tickets!L5 -> 2025-03-18 16:45:00 | D18: =IF(C18<>"",(C18-B18)*24,0) -> 54.5
A19: 4 | B19: =Tickets!J7 -> 2025-03-18 08:45:00 | C19: =Tickets!L7 -> 2025-03-19 12:30:00 | D19: =IF(C19<>"",(C19-B19)*24,0) -> 27.75
A20: 7 | B20: =Tickets!J10 -> 2025-03-21 14:00:00 | C20: =Tickets!L10 -> 2025-03-22 10:30:00 | D20: =IF(C20<>"",(C20-B20)*24,0) -> 20.5
A22: Average Resolution Time | D22: =IFERROR(AVERAGE(D18:D20),0) -> 34.25
A24: Escalation Rate Analysis
A25: Metric | B25: Value | C25: Percentage
A26: Total Tickets | B26: =$B$4 -> 8 | C26: =B26/$B$4 -> 1
A27: Escalated Tickets | B27: =0 -> 0 | C27: =B27/$B$4 -> 0
A28: Non-Escalated Tickets | B28: =$B$4-B27 -> 8 | C28: =B28/$B$4 -> 1
A29: Escalation Rate | B29: =C27 -> 0
A31: Most Common Issues Identification
A32: Issue Type | B32: Ticket Count | C32: Percentage
A33: Email notification not working | B33: =COUNTIF(Tickets!D4:D11,"Email notification not working") -> 2 | C33: =B33/$B$4 -> 0.25
A34: Login authentication failure | B34: =COUNTIF(Tickets!D4:D11,"Login authentication failure") -> 2 | C34: =B34/$B$4 -> 0.25
A35: API rate limiting issues | B35: =COUNTIF(Tickets!D4:D11,"API rate limiting issues") -> 1 | C35: =B35/$B$4 -> 0.125
A36: Database connection timeout | B36: =COUNTIF(Tickets!D4:D11,"Database connection timeout") -> 1 | C36: =B36/$B$4 -> 0.125
A37: Memory leak in background service | B37: =COUNTIF(Tickets!D4:D11,"Memory leak in background service") -> 1 | C37: =B37/$B$4 -> 0.125
A38: UI responsiveness issues | B38: =COUNTIF(Tickets!D4:D11,"UI responsiveness issues") -> 1 | C38: =B38/$B$4 -> 0.125
A40: Project-wise Ticket Analysis
A41: Project | B41: Ticket Count | C41: Percentage
A42: E-commerce Platform | B42: =COUNTIF(Tickets!B4:B11,"E-commerce Platform") -> 2 | C42: =B42/$B$4 -> 0.25
A43: Mobile App | B43: =COUNTIF(Tickets!B4:B11,"Mobile App") -> 2 | C43: =B43/$B$4 -> 0.25
A44: Admin Dashboard | B44: =COUNTIF(Tickets!B4:B11,"Admin Dashboard") -> 1 | C44: =B44/$B$4 -> 0.125
A45: API Gateway | B45: =COUNTIF(Tickets!B4:B11,"API Gateway") -> 2 | C45: =B45/$B$4 -> 0.25
A46: Customer Portal | B46: =COUNTIF(Tickets!B4:B11,"Customer Portal") -> 1 | C46: =B46/$B$4 -> 0.125
A48: Ticket Status Analysis
...

Sheet DASHBOARD
H1: TICKET MANAGEMENT SYSTEM ANALYSIS

Sheet Sheet2
